
2024-11-06 11:09:38.895754: E tensorflow/core/grappler/optimizers/dependency_optimizer.cc:697] Iteration = 0, topological sort failed with message: The graph couldn't be sorted in topological order.
2024-11-06 11:09:38.907837: E tensorflow/core/grappler/optimizers/dependency_optimizer.cc:697] Iteration = 1, topological sort failed with message: The graph couldn't be sorted in topological order.
2024-11-06 11:09:38.919432: E tensorflow/core/grappler/optimizers/meta_optimizer.cc:502] layout failed: Invalid argument: The graph couldn't be sorted in topological order.
2024-11-06 11:09:38.937673: E tensorflow/core/grappler/optimizers/meta_optimizer.cc:502] model_pruner failed: Invalid argument: MutableGraphView::MutableGraphView error: node 'loss/activation_1_loss/categorical_crossentropy/weighted_loss/concat' has self cycle fanin 'loss/activation_1_loss/categorical_crossentropy/weighted_loss/concat'.
2024-11-06 11:09:38.981236: E tensorflow/core/grappler/optimizers/meta_optimizer.cc:502] remapper failed: Invalid argument: MutableGraphView::MutableGraphView error: node 'loss/activation_1_loss/categorical_crossentropy/weighted_loss/concat' has self cycle fanin 'loss/activation_1_loss/categorical_crossentropy/weighted_loss/concat'.
2024-11-06 11:09:38.988960: E tensorflow/core/grappler/optimizers/meta_optimizer.cc:502] arithmetic_optimizer failed: Invalid argument: The graph couldn't be sorted in topological order.
2024-11-06 11:09:38.998510: E tensorflow/core/grappler/optimizers/dependency_optimizer.cc:697] Iteration = 0, topological sort failed with message: The graph couldn't be sorted in topological order.
2024-11-06 11:09:39.008660: E tensorflow/core/grappler/optimizers/dependency_optimizer.cc:697] Iteration = 1, topological sort failed with message: The graph couldn't be sorted in topological order.
2024-11-06 11:09:39.029097: W tensorflow/core/common_runtime/process_function_library_runtime.cc:675] Ignoring multi-device function optimization failure: Invalid argument: The graph couldn't be sorted in topological order.
2024-11-06 11:09:39.231200: I tensorflow/stream_executor/platform/default/dso_loader.cc:44] Successfully opened dynamic library cudnn64_7.dll
2024-11-06 11:10:14.665761: W tensorflow/stream_executor/cuda/redzone_allocator.cc:312] Internal: Invoking ptxas not supported on Windows
Relying on driver to perform ptx compilation. This message will be only logged once.
512/512 [==============================] - 47s 91ms/step - loss: 0.0848 - accuracy: 0.9673

Epoch 00001: saving model to tmp\vgg_unet_dental.00001
Traceback (most recent call last):
  File "c:/Users/Computer/Documents/GitHub/image-segmentation-keras/train_code_dental.py", line 41, in <module>
    model2.load_weights('models/modelW_dental.h5')
  File "C:\Users\Computer\anaconda3\envs\multiuresnet5\lib\site-packages\keras\engine\saving.py", line 492, in load_wrapper
    return load_function(*args, **kwargs)
  File "C:\Users\Computer\anaconda3\envs\multiuresnet5\lib\site-packages\keras\engine\network.py", line 1230, in load_weights
    f, self.layers, reshape=reshape)
  File "C:\Users\Computer\anaconda3\envs\multiuresnet5\lib\site-packages\keras\engine\saving.py", line 1237, in load_weights_from_hdf5_group
    K.batch_set_value(weight_value_tuples)
  File "C:\Users\Computer\anaconda3\envs\multiuresnet5\lib\site-packages\keras\backend\tensorflow_backend.py", line 2960, in batch_set_value
    tf_keras_backend.batch_set_value(tuples)
  File "C:\Users\Computer\anaconda3\envs\multiuresnet5\lib\site-packages\tensorflow_core\python\keras\backend.py", line 3343, in batch_set_value
    x.assign(np.asarray(value, dtype=dtype(x)))
  File "C:\Users\Computer\anaconda3\envs\multiuresnet5\lib\site-packages\tensorflow_core\python\ops\resource_variable_ops.py", line 814, in assign
    self._shape.assert_is_compatible_with(value_tensor.shape)
  File "C:\Users\Computer\anaconda3\envs\multiuresnet5\lib\site-packages\tensorflow_core\python\framework\tensor_shape.py", line 1115, in assert_is_compatible_with
    raise ValueError("Shapes %s and %s are incompatible" % (self, other))
ValueError: Shapes (3, 3, 64, 5) and (2, 64, 3, 3) are incompatible
